<?xml version="1.0" ?>
<robot name="mappingbot">
    <!-- 기본 뼈대가 되는 base link -->
    <link name="base_link">
        <visual>
            <geometry>
                <box size="0.167 0.24 0.15"/>
            </geometry>
            <material name="silver">
                <color rgba="0.75 0.75 0.75 1"/>
            </material>
        </visual>

        <!-- 시뮬레이션을 위한 물리데이터 정의 -->
        <collision>
            <geometry>
                <box size="0.167 0.24 0.15"/>
            </geometry>
        </collision>
        <inertial>
            <mass value="1.0"/>
            <inertia ixx="0.015" iyy="0.0375" izz="0.0375" ixy="0" ixz="0" iyz="0"/>
        </inertial>
    </link>

    <!-- 4개 바퀴와 축 정의 -->
    <link name="front_right_wheel">
        <visual>
            <geometry>
                <cylinder length="0.028" radius="0.0325"/>
            </geometry>
            <material name="black"/>
        </visual>

        <!-- 시뮬레이션을 위한 물리데이터 정의 -->
        <inertial>
            <mass value="0.1"/>
            <inertia ixx="0.00083" iyy="0.00083" izz="0.000167" ixy="0" ixz="0" iyz="0"/>
        </inertial>
    </link>
    <joint name="front_right_wheel_joint" type="continuous">
        <axis xyz="0 0 1"/>
        <parent link="base_link"/>
        <child link="front_right_wheel"/>
        <origin rpy="0 -1.5708 0" xyz="0.1 0.055 -0.08"/>
    </joint>

    <link name="front_left_wheel">
        <visual>
            <geometry>
                <cylinder length="0.028" radius="0.0325"/>
            </geometry>
            <material name="black"/>
        </visual>
        <!-- 시뮬레이션을 위한 물리데이터 정의 -->
        <inertial>
            <mass value="0.1"/>
            <inertia ixx="0.00083" iyy="0.00083" izz="0.000167" ixy="0" ixz="0" iyz="0"/>
        </inertial>
    </link>
    <joint name="front_left_wheel_joint" type="continuous">
        <axis xyz="0 0 1"/>
        <parent link="base_link"/>
        <child link="front_left_wheel"/>
        <origin rpy="0 -1.5708 0" xyz="-0.1 0.055 -0.08"/>
    </joint>

    <link name="back_right_wheel">
        <visual>
            <geometry>
                <cylinder length="0.028" radius="0.0325"/>
            </geometry>
            <material name="black"/>
        </visual>
        <!-- 시뮬레이션을 위한 물리데이터 정의 -->
        <inertial>
            <mass value="0.1"/>
            <inertia ixx="0.00083" iyy="0.00083" izz="0.000167" ixy="0" ixz="0" iyz="0"/>
        </inertial>
    </link>
    <joint name="back_right_wheel_joint" type="continuous">
        <axis xyz="0 0 1"/>
        <parent link="base_link"/>
        <child link="back_right_wheel"/>
        <origin rpy="0 -1.5708 0" xyz="0.1 -0.055 -0.08"/>
    </joint>
    <link name="back_left_wheel">
        <visual>
            <geometry>
                <cylinder length="0.028" radius="0.0325"/>
            </geometry>
            <material name="black"/>
        </visual>
        <!-- 시뮬레이션을 위한 물리데이터 정의 -->
        <inertial>
            <mass value="0.1"/>
            <inertia ixx="0.00083" iyy="0.00083" izz="0.000167" ixy="0" ixz="0" iyz="0"/>
        </inertial>
    </link>
    <joint name="back_left_wheel_joint" type="continuous">
        <axis xyz="0 0 1"/>
        <parent link="base_link"/>
        <child link="back_left_wheel"/>
        <origin rpy="0 -1.5708 0" xyz="-0.1 -0.055 -0.08"/>
    </joint>


    <!-- Add Laser Sensor -->
    <link name="camera_base_link">
        <collision>
            <origin xyz="0 0 0" rpy="0 0 0"/>
            <geometry>
                <box size = "0.1 0.1 0.1"/>
            </geometry>
        </collision>
        <visual>
            <origin xyz="0 0 0" rpy="0 0 0"/>
            <geometry>
                <box size="0.1 0.1 0.1"/>
            </geometry>
        </visual>
        <inertial>
            <mass value="1e-5"/>
            <origin xyz="0 0 0" rpy="0 0 0"/>
            <inertia ixx="1e-6" ixy="0" ixz="0" iyy="1e-6" iyz="0" izz="1e-6"/>
        </inertial>
    </link>
    <joint name="camera_link_joint" type="fixed">
        <axis xyz="0 1 0" />
        <origin xyz="0 0 0.2" rpy="0 0 0"/>
        <parent link="base_link"/>
        <child link="camera_base_link"/>
    </joint>

    <!--Define Laser Sensor -->
    <gazebo reference="camera_base_link">
        <sensor type="gpy_ray" name="hokuyo">
            <pose>0 0 0 0 0 0</pose>
            <visualize>false</visualize>
            <update_rate>40</update_rate>
            <ray>
                <scan>
                    <horizontal>
                        <samples>720</samples>
                        <resolution>1</resolution>
                        <min_angle>-1.570796</min_angle>
                        <max_angle>1.570796</max_angle>
                    </horizontal>
                </scan>
                <range>
                    <min>0.10</min>
                    <max>30.0</max>
                    <resolution>0.01</resolution>
                </range>
            </ray>
            <plugin name="gpu_laser" filename="libgazebo_ros_gpu_laser.so">
                <topicName>/scan</topicName>
                <frameName>camera_base_link</frameName>
            </plugin>
        </sensor>
    </gazebo>


</robot>