<?xml version="1.0" ?>
<robot name="mappingbot">
    <link name="base_link">
        <visual>
            <geometry>
                <box size="0.167 0.24 0.15"/>
            </geometry>
            <material name="silver">
                <color rgba="0.75 0.75 0.75 1"/>
            </material>
        </visual>
        <collision>
            <geometry>
                <box size="0.167 0.24 0.15"/>
            </geometry>
        </collision>
        <inertial>
            <mass value="1.0"/>
            <inertia ixx="0.015" iyy="0.0375" izz="0.0375" ixy="0" ixz="0" iyz="0"/>
        </inertial>
    </link>


    <link name="front_right_wheel">
        <visual>
            <geometry>
                <cylinder length="0.028" radius="0.0325"/>
            </geometry>
            <material name="black"/>
        </visual>
        <inertial>
            <mass value="0.1"/>
            <inertia ixx="5.1458e-5" iyy="5.1458e-5" izz="6.125e-5" ixy="0" ixz="0" iyz="0"/>
        </inertial>
    </link>
    <joint name="front_right_wheel_joint" type="continuous">
        <axis xyz="0 0 1"/>
        <parent link="base_link"/>
        <child link="front_right_wheel"/>
        <origin rpy="0 -1.5708 0" xyz="0.1 0.055 -0.04"/>
    </joint>



    <link name="front_left_wheel">
        <visual>
            <geometry>
                <cylinder length="0.028" radius="0.0325"/>
            </geometry>
            <material name="black"/>
        </visual>
        <inertial>
            <mass value="0.1"/>
            <inertia ixx="5.1458e-5" iyy="5.1458e-5" izz="6.125e-5" ixy="0" ixz="0" iyz="0"/>
        </inertial>
    </link>
    <joint name="front_left_wheel_joint" type="continuous">
        <axis xyz="0 0 1"/>
        <parent link="base_link"/>
        <child link="front_left_wheel"/>
        <origin rpy="0 -1.5708 0" xyz="-0.1 0.055 -0.04"/>
    </joint>



    <link name="back_right_wheel">
        <visual>
            <geometry>
                <cylinder length="0.028" radius="0.0325"/>
            </geometry>
            <material name="black"/>
        </visual>
        <inertial>
            <mass value="0.1"/>
            <inertia ixx="5.1458e-5" iyy="5.1458e-5" izz="6.125e-5" ixy="0" ixz="0" iyz="0"/>
         </inertial>
    </link>
    <joint name="back_right_wheel_joint" type="continuous">
        <axis xyz="0 0 1"/>
        <parent link="base_link"/>
        <child link="back_right_wheel"/>
        <origin rpy="0 -1.5708 0" xyz="0.1 -0.055 -0.04"/>
    </joint>



    <link name="back_left_wheel">
        <visual>
            <geometry>
                <cylinder length="0.028" radius="0.0325"/>
            </geometry>
            <material name="black"/>
        </visual>
        <inertial>
            <mass value="0.1"/>
            <inertia ixx="5.1458e-5" iyy="5.1458e-5" izz="6.125e-5" ixy="0" ixz="0" iyz="0"/>
        </inertial>
    </link>
    <joint name="back_left_wheel_joint" type="continuous">
        <axis xyz="0 0 1"/>
        <parent link="base_link"/>
        <child link="back_left_wheel"/>
        <origin rpy="0 -1.5708 0" xyz="-0.1 -0.055 -0.04"/>
    </joint>



    <link name="camera_base_link">
        <collision>
            <origin xyz="0 0 0" rpy="0 0 0"/>
            <geometry>
                <box size = "0.281 0.06 0.033"/>
            </geometry>
        </collision>
        <visual>
            <origin xyz="0 0 0" rpy="0 0 0"/>
            <geometry>
                <box size = "0.281 0.06 0.033"/>
            </geometry>
        </visual>
        <inertial>
            <mass value="1e-5"/>
            <origin xyz="0 0 0" rpy="0 0 0"/>
            <inertia ixx="1e-6" ixy="0" ixz="0" iyy="1e-6" iyz="0" izz="1e-6"/>
        </inertial>
    </link>
    <joint name="camera_link_joint" type="fixed">
        <axis xyz="0 1 0" />
        <origin xyz="0 0.065 0.125" rpy="0 0 0"/>
        <parent link="base_link"/>
        <child link="camera_base_link"/>
    </joint>





    <gazebo>
        <plugin name="differential_drive_controller" filename="libdiffdrive_plugin.so">
            <leftJoint>front_left_wheel_joint</leftJoint>
            <rightJoint>front_right_wheel_joint</rightJoint>
            <robotBaseFrame>base_link</robotBaseFrame>
            <wheelSeperation>0.25</wheelSeperation>
            <wheelDiameter>0.07</wheelDiameter>
            <publishWheelJointState>true</publishWheelJointState>
        </plugin>
    </gazebo>

    <gazebo reference="camera_base_link">
        <plugin name="camera_base_link_controller" filename="libgazebo_ros_openni_kinect.so">
            <topicName>/scan</topicName>
            <frameName>camera_base_link</frameName>
            <baseline>0.2</baseline>
            <alwaysOn>true</alwaysOn>
            <updateRate>1.0</updateRate>
            <cameraName>camera_ir</cameraName>
            <imageTopicName>/camera/depth/image_raw</imageTopicName>
            <cameraInfoTopicName>/camera/depth/camera_info</cameraInfoTopicName>
            <depthImageTopicName>/camera/depth/image_raw</depthImageTopicName>
            <depthImageInfoTopicName>/camera/depth/camera_info</depthImageInfoTopicName>
            <pointCloudTopicName>/camera/depth/points</pointCloudTopicName>
            <frameName>camera_base_link</frameName>
            <pointCloudCutoff>0.5</pointCloudCutoff>
            <distortionK1>0.00000001</distortionK1>
            <distortionK2>0.00000001</distortionK2>
            <distortionK3>0.00000001</distortionK3>
            <distortionT1>0.00000001</distortionT1>
            <distortionT2>0.00000001</distortionT2>
            <CxPrime>0</CxPrime>
            <Cx>0</Cx>
            <Cy>0</Cy>
            <focalLength>0</focalLength>
            <hackBaseline>0</hackBaseline>
        </plugin>
    </gazebo>


</robot>